<?xml version="1.0"?>
<robot name="UGV">
  <link name="base_link">
    <visual>
      <geometry>
        <box size="0.8 0.4 0.2"/>
      </geometry>
      <material name="blue">
        <color rgba="0.0 0.0 0.8 1.0"/>
      </material>
    </visual>
  </link>

  <link name="link_2">
    <visual>
      <geometry>
        <cylinder radius="0.1" length="0.1"/>
      </geometry>
      <material name="black">
        <color rgba="0.0 0.0 0.0 1.0"/>
      </material>
    </visual>
  </link>

  <link name="link_3">
    <visual>
      <geometry>
        <cylinder radius="0.1" length="0.1"/>
      </geometry>
      <material name="black">
        <color rgba="0.0 0.0 0.0 1.0"/>
      </material>
    </visual>
  </link>

  <link name="link_4">
    <visual>
      <geometry>
        <cylinder radius="0.1" length="0.1"/>
      </geometry>
      <material name="black">
        <color rgba="0.0 0.0 0.0 1.0"/>
      </material>
    </visual>
  </link>

  <link name="link_5">
    <visual>
      <geometry>
        <cylinder radius="0.1" length="0.1"/>
      </geometry>
      <material name="black">
        <color rgba="0.0 0.0 0.0 1.0"/>
      </material>
    </visual>
  </link>

  <joint name="joint_1ame" type="continuous">
    <origin xyz="0.35 0.25 -0.06" rpy="1.57 0.0 0.0"/>
    <parent link="base_link"/>
    <child link="link_2"/>
    <axis xyz="0.0 1.0 0.0"/>
  </joint>

   <joint name="joint_2ame" type="continuous">
    <origin xyz="0.35 -0.25 -0.06"  rpy="1.57 0.0 0.0"/>
    <parent link="base_link"/>
    <child link="link_3"/>
    <axis xyz="0.0 1.0 0.0"/>
  </joint>

  <joint name="joint_3ame" type="continuous">
    <origin xyz="-0.35 -0.25 -0.06"  rpy="1.57 0.0 0.0"/>
    <parent link="base_link"/>
    <child link="link_4"/>
    <axis xyz="0.0 1.0 0.0"/>
 </joint>
 
<joint name="joint_4ame" type="continuous">
    <origin xyz="-0.35 0.25 -0.06"  rpy="1.57 0.0 0.0"/>
    <parent link="base_link"/>
    <child link="link_5"/>
    <axis xyz="0.0 1.0 0.0"/>
 </joint>
</robot>
