<?xml version="1.0" encoding="utf-8"?>
<!-- This URDF was automatically created by SolidWorks to URDF Exporter! Originally created by Stephen Brawner (brawner@gmail.com) 
     Commit Version: 1.6.0-1-g15f4949  Build Version: 1.6.7594.29634
     For more information, please see http://wiki.ros.org/sw_urdf_exporter -->
<robot
  name="assem1">
  <link
    name="base_link">
    <inertial>
      <origin
        xyz="0.36034 0.11422 0.25"
        rpy="0 0 0" />
      <mass
        value="1600.6" />
      <inertia
        ixx="54.717"
        ixy="0.0065005"
        ixz="-2.0028E-15"
        iyy="166.78"
        iyz="1.9167E-16"
        izz="154.75" />
    </inertial>
    <visual>
      <origin
        xyz="0 0 0"
        rpy="0 0 0" />
      <geometry>
        <mesh
          filename="package://Assem1/meshes/base_link.STL" />
      </geometry>
      <material
        name="">
        <color
          rgba="0.64706 0.61961 0.58824 1" />
      </material>
    </visual>
    <collision>
      <origin
        xyz="0 0 0"
        rpy="0 0 0" />
      <geometry>
        <mesh
          filename="package://Assem1/meshes/base_link.STL" />
      </geometry>
    </collision>
  </link>
  <link
    name="Lidar_link">
    <inertial>
      <origin
        xyz="-0.61136 0.36424 0.25101"
        rpy="0 0 0" />
      <mass
        value="97.167" />
      <inertia
        ixx="1.0813"
        ixy="-6.9269E-18"
        ixz="0.011454"
        iyy="1.9678"
        iyz="2.3424E-17"
        izz="1.0484" />
    </inertial>
    <visual>
      <origin
        xyz="0 0 0"
        rpy="0 0 0" />
      <geometry>
        <mesh
          filename="package://Assem1/meshes/Lidar_link.STL" />
      </geometry>
      <material
        name="">
        <color
          rgba="0.64706 0.61961 0.58824 1" />
      </material>
    </visual>
    <collision>
      <origin
        xyz="0 0 0"
        rpy="0 0 0" />
      <geometry>
        <mesh
          filename="package://Assem1/meshes/Lidar_link.STL" />
      </geometry>
    </collision>
  </link>
  <joint
    name="LiDar joint"
    type="fixed">
    <origin
      xyz="0.7375 0 0"
      rpy="0 0 0" />
    <parent
      link="base_link" />
    <child
      link="Lidar_link" />
    <axis
      xyz="0 0 0" />
  </joint>
  <link
    name="banh1_Link">
    <inertial>
      <origin
        xyz="-0.00012964 -0.00051731 0.525"
        rpy="0 0 0" />
      <mass
        value="12.33" />
      <inertia
        ixx="0.033608"
        ixy="9.0745E-05"
        ixz="-2.0098E-20"
        iyy="0.033953"
        iyz="-1.4497E-19"
        izz="0.062424" />
    </inertial>
    <visual>
      <origin
        xyz="0 0 0"
        rpy="0 0 0" />
      <geometry>
        <mesh
          filename="package://Assem1/meshes/banh1_Link.STL" />
      </geometry>
      <material
        name="">
        <color
          rgba="0.64706 0.61961 0.58824 1" />
      </material>
    </visual>
    <collision>
      <origin
        xyz="0 0 0"
        rpy="0 0 0" />
      <geometry>
        <mesh
          filename="package://Assem1/meshes/banh1_Link.STL" />
      </geometry>
    </collision>
  </link>
  <joint
    name="banh1 joint"
    type="continuous">
    <origin
      xyz="0.7375 0 0"
      rpy="0 0 0" />
    <parent
      link="base_link" />
    <child
      link="banh1_Link" />
    <axis
      xyz="0 0 -1" />
    <limit
      effort="10"
      velocity="5" />
    <dynamics
      damping="0.1"
      friction="0.1" />
  </joint>
  <link
    name="banh2_Link">
    <inertial>
      <origin
        xyz="0.00051969 -0.00011976 -0.025"
        rpy="0 0 0" />
      <mass
        value="12.33" />
      <inertia
        ixx="0.033955"
        ixy="-8.6313E-05"
        ixz="2.827E-19"
        iyy="0.033606"
        iyz="-5.7388E-20"
        izz="0.062424" />
    </inertial>
    <visual>
      <origin
        xyz="0 0 0"
        rpy="0 0 0" />
      <geometry>
        <mesh
          filename="package://Assem1/meshes/banh2_Link.STL" />
      </geometry>
      <material
        name="">
        <color
          rgba="0.64706 0.61961 0.58824 1" />
      </material>
    </visual>
    <collision>
      <origin
        xyz="0 0 0"
        rpy="0 0 0" />
      <geometry>
        <mesh
          filename="package://Assem1/meshes/banh2_Link.STL" />
      </geometry>
    </collision>
  </link>
  <joint
    name="banh2 joint"
    type="continuous">
    <origin
      xyz="0.7375 0 0"
      rpy="0 0 0" />
    <parent
      link="base_link" />
    <child
      link="banh2_Link" />
    <axis
      xyz="0 0 1" />
    <limit
      effort="10"
      velocity="5" />
    <dynamics
      damping="0.1"
      friction="0.1" />
  </joint>
  <link
    name="banh3_Link">
    <inertial>
      <origin
        xyz="-0.7379 0.00034776 -0.025"
        rpy="0 0 0" />
      <mass
        value="12.33" />
      <inertia
        ixx="0.033808"
        ixy="-0.0001927"
        ixz="1.0054E-18"
        iyy="0.033753"
        iyz="-3.2578E-18"
        izz="0.062424" />
    </inertial>
    <visual>
      <origin
        xyz="0 0 0"
        rpy="0 0 0" />
      <geometry>
        <mesh
          filename="package://Assem1/meshes/banh3_Link.STL" />
      </geometry>
      <material
        name="">
        <color
          rgba="0.64706 0.61961 0.58824 1" />
      </material>
    </visual>
    <collision>
      <origin
        xyz="0 0 0"
        rpy="0 0 0" />
      <geometry>
        <mesh
          filename="package://Assem1/meshes/banh3_Link.STL" />
      </geometry>
    </collision>
  </link>
  <joint
    name="banh3 joint"
    type="continuous">
    <origin
      xyz="0.7375 0 0"
      rpy="0 0 0" />
    <parent
      link="base_link" />
    <child
      link="banh3_Link" />
    <axis
      xyz="0 0 1" />
    <limit
      effort="10"
      velocity="5" />
    <dynamics
      damping="0.1"
      friction="0.1" />
  </joint>
  <link
    name="banh4_Link">
    <inertial>
      <origin
        xyz="-0.73708 0.00032504 0.525"
        rpy="0 0 0" />
      <mass
        value="12.33" />
      <inertia
        ixx="0.033829"
        ixy="0.00018848"
        ixz="1.6737E-19"
        iyy="0.033732"
        iyz="9.6808E-19"
        izz="0.062424" />
    </inertial>
    <visual>
      <origin
        xyz="0 0 0"
        rpy="0 0 0" />
      <geometry>
        <mesh
          filename="package://Assem1/meshes/banh4_Link.STL" />
      </geometry>
      <material
        name="">
        <color
          rgba="0.64706 0.61961 0.58824 1" />
      </material>
    </visual>
    <collision>
      <origin
        xyz="0 0 0"
        rpy="0 0 0" />
      <geometry>
        <mesh
          filename="package://Assem1/meshes/banh4_Link.STL" />
      </geometry>
    </collision>
  </link>
  <joint
    name="banh4 joint"
    type="continuous">
    <origin
      xyz="0.7375 0 0"
      rpy="0 0 0" />
    <parent
      link="base_link" />
    <child
      link="banh4_Link" />
    <axis
      xyz="0 0 -1" />
    <limit
      effort="10"
      velocity="5" />
    <dynamics
      damping="0.1"
      friction="0.1" />
  </joint>
</robot>