<?xml version="1.0"?>
<robot name="robot_name">
    <link name="base_link">
    <visual>
      <origin rpy="3.1416 0 0" xyz="0 0 0"/>
      <geometry>
        <mesh filename="package://mobile_robot/stk_link/part1.stl" scale=" 0.05 0.05 0.05 " />
      </geometry>
    </visual>
  </link>
    <link name="base_link_2">
    <visual>
      <origin rpy="0 0 0" xyz="0 0 0"/>
      <geometry>
        <mesh filename="package://mobile_robot/stk_link/part2.stl" scale=" 0.05 0.05 0.05 " />
      </geometry>
    </visual>
  </link>
   <joint name="base_link_to_base_link_2" type="continuous">
    <parent link="base_link"/>
    <child link="base_link_2"/>
    <origin xyz="0.2 -0.04 -0.25" rpy="0 0 0"/>
  </joint>
  <link name="base_link_3">
    <visual>
      <origin rpy="0 0 0" xyz="0 0 0"/>
      <geometry>
        <mesh filename="package://mobile_robot/stk_link/part2.stl" scale=" 0.05 0.05 0.05 " />
      </geometry>
    </visual>
  </link>
   <joint name="base_link_to_base_link_3" type="continuous">
    <parent link="base_link"/>
    <child link="base_link_3"/>
    <origin xyz="0.77 -0.04 -0.25" rpy="0 0 0"/>
  </joint>
   <link name="base_link_4">
    <visual>
      <origin rpy="0 0 0" xyz="0 0 0"/>
      <geometry>
        <mesh filename="package://mobile_robot/stk_link/part2.stl" scale=" 0.05 0.05 0.05 " />
      </geometry>
    </visual>
  </link>
   <joint name="base_link_to_base_link_4" type="continuous">
    <parent link="base_link"/>
    <child link="base_link_4"/>
    <origin xyz="0.77 -0.46 -0.1 " rpy="3.1416 0 0"/>
  </joint>
    <link name="base_link_5">
      <visual>
       <origin rpy="0 0 0" xyz="0 0 0"/>
        <geometry>
        <mesh filename="package://mobile_robot/stk_link/part2.stl" scale=" 0.05 0.05 0.05 " />
       </geometry>
      </visual>
    </link>
   <joint name="base_link_to_base_link_5" type="continuous">
    <parent link="base_link"/>
    <child link="base_link_5"/>
    <origin xyz="0.2 -0.46 -0.1 " rpy="3.1416 0 0"/>
  </joint>
</robot>

